Workbook

Sheet CLEANED DATA
A1: OrderID | B1: OrderDate | C1: SalesChannel cleaned | D1: CustomerID | E1: CustomerName cleaned | F1: City cleaned | G1: Region | H1: SalespersonID | I1: Sales Person Name | J1: ProductID | K1: ProductCategory | L1: ProductName | M1: Quantity | N1: UnitPrice2 | O1: Total Revenue
A2: ORD1000 | B2: 45349 | C2: =IF(TRIM(sales_dataset[[#This Row],[SalesChannel]])="",sales_dataset!C3,PROPER(TRIM(sales_dataset[[#This Row],[SalesChannel]]))) -> Online | D2: CUST168 | E2: =IF(TRIM(sales_dataset[[#This Row],[CustomerName]])="",sales_dataset!F8, PROPER(TRIM(sales_dataset[[#This Row],[CustomerName]]))) -> Priya | F2: =IF(TRIM(sales_dataset[[#This Row],[City]])="", sales_dataset!$H$3, PROPER(TRIM(sales_dataset[[#This Row],[City]]))) -> Delhi | G2: =PROPER(sales_dataset[[#This Row],[Region cleaned]]) -> North | H2: SP36 | I2: =IF(TRIM(sales_dataset[[#This Row],[SalespersonName]])="",I5,PROPER(TRIM(sales_dataset[[#This Row],[SalespersonName]]))) -> Kevin | J2: PROD73 | K2: =PROPER(sales_dataset[[#This Row],[ProductCategory cleaned]]) -> Home | L2: =PROPER(sales_dataset[[#This Row],[ProductName]]) -> Tv | M2: =ABS(sales_dataset!W:W) -> 1 | N2: =ABS(sales_dataset[[#This Row],[Column4]]) -> 1500 | O2: =M2*N2 -> 1500
A3: ORD1001 | B3: 45304 | C3: =IF(TRIM(sales_dataset[[#This Row],[SalesChannel]])="",sales_dataset!C4,PROPER(TRIM(sales_dataset[[#This Row],[SalesChannel]]))) -> Offline | D3: CUST177 | E3: =IF(TRIM(sales_dataset[[#This Row],[CustomerName]])="",sales_dataset!F9, PROPER(TRIM(sales_dataset[[#This Row],[CustomerName]]))) -> Sara | F3: =IF(TRIM(sales_dataset[[#This Row],[City]])="", sales_dataset!$H$3, PROPER(TRIM(sales_dataset[[#This Row],[City]]))) -> Delhi | G3: =PROPER(sales_dataset[[#This Row],[Region cleaned]]) -> North | H3: SP7 | I3: =IF(TRIM(sales_dataset[[#This Row],[SalespersonName]])="",I6,PROPER(TRIM(sales_dataset[[#This Row],[SalespersonName]]))) -> Raj | J3: PROD26 | K3: =PROPER(sales_dataset[[#This Row],[ProductCategory cleaned]]) -> Electronics | L3: =PROPER(sales_dataset[[#This Row],[ProductName]]) -> Shirt | M3: =ABS(sales_dataset!W:W) -> 4 | N3: =ABS(sales_dataset[[#This Row],[Column4]]) -> 100 | O3: =M3*N3 -> 400
A4: ORD1002 | B4: 45432 | C4: =IF(TRIM(sales_dataset[[#This Row],[SalesChannel]])="",sales_dataset!C5,PROPER(TRIM(sales_dataset[[#This Row],[SalesChannel]]))) -> Store | D4: CUST2 | E4: =IF(TRIM(sales_dataset[[#This Row],[CustomerName]])="",sales_dataset!F10, PROPER(TRIM(sales_dataset[[#This Row],[CustomerName]]))) -> Priya | F4: =IF(TRIM(sales_dataset[[#This Row],[City]])="", sales_dataset!$H$3, PROPER(TRIM(sales_dataset[[#This Row],[City]]))) -> Delhi | G4: =PROPER(sales_dataset[[#This Row],[Region cleaned]]) -> North | H4: SP21 | I4: =IF(TRIM(sales_dataset[[#This Row],[SalespersonName]])="",I7,PROPER(TRIM(sales_dataset[[#This Row],[SalespersonName]]))) -> Megha | J4: PROD76 | K4: =PROPER(sales_dataset[[#This Row],[ProductCategory cleaned]]) -> Home | L4: =PROPER(sales_dataset[[#This Row],[ProductName]]) -> Shirt | M4: =ABS(sales_dataset!W:W) -> 2 | N4: =ABS(sales_dataset[[#This Row],[Column4]]) -> 100 | O4: =M4*N4 -> 200
A5: ORD1003 | B5: 45417 | C5: =IF(TRIM(sales_dataset[[#This Row],[SalesChannel]])="",sales_dataset!C6,PROPER(TRIM(sales_dataset[[#This Row],[SalesChannel]]))) -> Store | D5: CUST193 | E5: =IF(TRIM(sales_dataset[[#This Row],[CustomerName]])="",sales_dataset!F11, PROPER(TRIM(sales_dataset[[#This Row],[CustomerName]]))) -> Priya | F5: =IF(TRIM(sales_dataset[[#This Row],[City]])="", sales_dataset!$H$3, PROPER(TRIM(sales_dataset[[#This Row],[City]]))) -> Hyderabad | G5: =PROPER(sales_dataset[[#This Row],[Region cleaned]]) -> North | H5: SP16 | I5: =IF(TRIM(sales_dataset[[#This Row],[SalespersonName]])="",I8,PROPER(TRIM(sales_dataset[[#This Row],[SalespersonName]]))) -> Sam | J5: PROD70 | K5: =PROPER(sales_dataset[[#This Row],[ProductCategory cleaned]]) -> Electronics | L5: =PROPER(sales_dataset[[#This Row],[ProductName]]) -> Tv | M5: =ABS(sales_dataset!W:W) -> 5 | N5: =ABS(sales_dataset[[#This Row],[Column4]]) -> 1500 | O5: =M5*N5 -> 7500
A6: ORD1004 | B6: 45406 | C6: =IF(TRIM(sales_dataset[[#This Row],[SalesChannel]])="",sales_dataset!C7,PROPER(TRIM(sales_dataset[[#This Row],[SalesChannel]]))) -> Online | D6: CUST198 | E6: =IF(TRIM(sales_dataset[[#This Row],[CustomerName]])="",sales_dataset!F12, PROPER(TRIM(sales_dataset[[#This Row],[CustomerName]]))) -> Priya | F6: =IF(TRIM(sales_dataset[[#This Row],[City]])="", sales_dataset!$H$3, PROPER(TRIM(sales_dataset[[#This Row],[City]]))) -> Bengaluru | G6: =PROPER(sales_dataset[[#This Row],[Region cleaned]]) -> West | H6: SP30 | I6: =IF(TRIM(sales_dataset[[#This Row],[SalespersonName]])="",I9,PROPER(TRIM(sales_dataset[[#This Row],[SalespersonName]]))) -> Anita | J6: PROD24 | K6: =PROPER(sales_dataset[[#This Row],[ProductCategory cleaned]]) -> Home | L6: =PROPER(sales_dataset[[#This Row],[ProductName]]) -> Tv | M6: =ABS(sales_dataset!W:W) -> 1 | N6: =ABS(sales_dataset[[#This Row],[Column4]]) -> 100 | O6: =M6*N6 -> 100
A7: ORD1005 | B7: 45363 | C7: =IF(TRIM(sales_dataset[[#This Row],[SalesChannel]])="",sales_dataset!C8,PROPER(TRIM(sales_dataset[[#This Row],[SalesChannel]]))) -> Online | D7: CUST28 | E7: =IF(TRIM(sales_dataset[[#This Row],[CustomerName]])="",sales_dataset!F13, PROPER(TRIM(sales_dataset[[#This Row],[CustomerName]]))) -> Amit | F7: =IF(TRIM(sales_dataset[[#This Row],[City]])="", sales_dataset!$H$3, PROPER(TRIM(sales_dataset[[#This Row],[City]]))) -> Delhi | G7: =PROPER(sales_dataset[[#This Row],[Region cleaned]]) -> North | H7: SP8 | I7: =IF(TRIM(sales_dataset[[#This Row],[SalespersonName]])="",I10,PROPER(TRIM(sales_dataset[[#This Row],[SalespersonName]]))) -> Sam | J7: PROD88 | K7: =PROPER(sales_dataset[[#This Row],[ProductCategory cleaned]]) -> Clothing | L7: =PROPER(sales_dataset[[#This Row],[ProductName]]) -> Shirt | M7: =ABS(sales_dataset!W:W) -> 1 | N7: =ABS(sales_dataset[[#This Row],[Column4]]) -> 1500 | O7: =M7*N7 -> 1500
A8: ORD1006 | B8: 45344 | C8: =IF(TRIM(sales_dataset[[#This Row],[SalesChannel]])="",sales_dataset!C9,PROPER(TRIM(sales_dataset[[#This Row],[SalesChannel]]))) -> Online | D8: CUST200 | E8: =IF(TRIM(sales_dataset[[#This Row],[CustomerName]])="",sales_dataset!F14, PROPER(TRIM(sales_dataset[[#This Row],[CustomerName]]))) -> Priya | F8: =IF(TRIM(sales_dataset[[#This Row],[City]])="", sales_dataset!$H$3, PROPER(TRIM(sales_dataset[[#This Row],[City]]))) -> Delhi | G8: =PROPER(sales_dataset[[#This Row],[Region cleaned]]) -> West | H8: SP18 | I8: =IF(TRIM(sales_dataset[[#This Row],[SalespersonName]])="",I11,PROPER(TRIM(sales_dataset[[#This Row],[SalespersonName]]))) -> Megha | J8: PROD99 | K8: =PROPER(sales_dataset[[#This Row],[ProductCategory cleaned]]) -> Clothing | L8: =PROPER(sales_dataset[[#This Row],[ProductName]]) -> Laptop | M8: =ABS(sales_dataset!W:W) -> 1 | N8: =ABS(sales_dataset[[#This Row],[Column4]]) -> 500 | O8: =M8*N8 -> 500
A9: ORD1007 | B9: 45571 | C9: =IF(TRIM(sales_dataset[[#This Row],[SalesChannel]])="",sales_dataset!C10,PROPER(TRIM(sales_dataset[[#This Row],[SalesChannel]]))) -> Offline | D9: CUST109 | E9: =IF(TRIM(sales_dataset[[#This Row],[CustomerName]])="",sales_dataset!F15, PROPER(TRIM(sales_dataset[[#This Row],[CustomerName]]))) -> John | F9: =IF(TRIM(sales_dataset[[#This Row],[City]])="", sales_dataset!$H$3, PROPER(TRIM(sales_dataset[[#This Row],[City]]))) -> Mumbai | G9: =PROPER(sales_dataset[[#This Row],[Region cleaned]]) -> North | H9: SP29 | I9: =IF(TRIM(sales_dataset[[#This Row],[SalespersonName]])="",I12,PROPER(TRIM(sales_dataset[[#This Row],[SalespersonName]]))) -> Raj | J9: PROD71 | K9: =PROPER(sales_dataset[[#This Row],[ProductCategory cleaned]]) -> Home | L9: =PROPER(sales_dataset[[#This Row],[ProductName]]) -> Sofa | M9: =ABS(sales_dataset!W:W) -> 4 | N9: =ABS(sales_dataset[[#This Row],[Column4]]) -> 2500 | O9: =M9*N9 -> 10000
A10: ORD1008 | B10: 45336 | C10: =IF(TRIM(sales_dataset[[#This Row],[SalesChannel]])="",sales_dataset!C11,PROPER(TRIM(sales_dataset[[#This Row],[SalesChannel]]))) -> Store | D10: CUST57 | E10: =IF(TRIM(sales_dataset[[#This Row],[CustomerName]])="",sales_dataset!F16, PROPER(TRIM(sales_dataset[[#This Row],[CustomerName]]))) -> Priya | F10: =IF(TRIM(sales_dataset[[#This Row],[City]])="", sales_dataset!$H$3, PROPER(TRIM(sales_dataset[[#This Row],[City]]))) -> Mumbai | G10: =PROPER(sales_dataset[[#This Row],[Region cleaned]]) -> East | H10: SP16 | I10: =IF(TRIM(sales_dataset[[#This Row],[SalespersonName]])="",I13,PROPER(TRIM(sales_dataset[[#This Row],[SalespersonName]]))) -> Megha | J10: PROD4 | K10: =PROPER(sales_dataset[[#This Row],[ProductCategory cleaned]]) -> Electronics | L10: =PROPER(sales_dataset[[#This Row],[ProductName]]) -> Laptop | M10: =ABS(sales_dataset!W:W) -> 5 | N10: =ABS(sales_dataset[[#This Row],[Column4]]) -> 100 | O10: =M10*N10 -> 500
A11: ORD1009 | B11: 45508 | C11: =IF(TRIM(sales_dataset[[#This Row],[SalesChannel]])="",sales_dataset!C12,PROPER(TRIM(sales_dataset[[#This Row],[SalesChannel]]))) -> Store | D11: CUST46 | E11: =IF(TRIM(sales_dataset[[#This Row],[CustomerName]])="",sales_dataset!F17, PROPER(TRIM(sales_dataset[[#This Row],[CustomerName]]))) -> Sara | F11: =IF(TRIM(sales_dataset[[#This Row],[City]])="", sales_dataset!$H$3, PROPER(TRIM(sales_dataset[[#This Row],[City]]))) -> Delhi | G11: =PROPER(sales_dataset[[#This Row],[Region cleaned]]) -> North | H11: SP10 | I11: =IF(TRIM(sales_dataset[[#This Row],[SalespersonName]])="",I14,PROPER(TRIM(sales_dataset[[#This Row],[SalespersonName]]))) -> Raj | J11: PROD94 | K11: =PROPER(sales_dataset[[#This Row],[ProductCategory cleaned]]) -> Clothing | L11: =PROPER(sales_dataset[[#This Row],[ProductName]]) -> Shirt | M11: =ABS(sales_dataset!W:W) -> 3 | N11: =ABS(sales_dataset[[#This Row],[Column4]]) -> 2000 | O11: =M11*N11 -> 6000
A12: ORD1010 | B12: 45308 | C12: =IF(TRIM(sales_dataset[[#This Row],[SalesChannel]])="",sales_dataset!C13,PROPER(TRIM(sales_dataset[[#This Row],[SalesChannel]]))) -> Online | D12: CUST179 | E12: =IF(TRIM(sales_dataset[[#This Row],[CustomerName]])="",sales_dataset!F18, PROPER(TRIM(sales_dataset[[#This Row],[CustomerName]]))) -> Priya | F12: =IF(TRIM(sales_dataset[[#This Row],[City]])="", sales_dataset!$H$3, PROPER(TRIM(sales_dataset[[#This Row],[City]]))) -> Mumbai | G12: =PROPER(sales_dataset[[#This Row],[Region cleaned]]) -> East | H12: SP7 | I12: =IF(TRIM(sales_dataset[[#This Row],[SalespersonName]])="",I15,PROPER(TRIM(sales_dataset[[#This Row],[SalespersonName]]))) -> Raj | J12: PROD60 | K12: =PROPER(sales_dataset[[#This Row],[ProductCategory cleaned]]) -> Electronics | L12: =PROPER(sales_dataset[[#This Row],[ProductName]]) -> Tv | M12: =ABS(sales_dataset!W:W) -> 4 | N12: =ABS(sales_dataset[[#This Row],[Column4]]) -> 0 | O12: =M12*N12 -> 0
A13: ORD1011 | B13: 45307 | C13: =IF(TRIM(sales_dataset[[#This Row],[SalesChannel]])="",sales_dataset!C14,PROPER(TRIM(sales_dataset[[#This Row],[SalesChannel]]))) -> Online | D13: CUST133 | E13: =IF(TRIM(sales_dataset[[#This Row],[CustomerName]])="",sales_dataset!F19, PROPER(TRIM(sales_dataset[[#This Row],[CustomerName]]))) -> Sara | F13: =IF(TRIM(sales_dataset[[#This Row],[City]])="", sales_dataset!$H$3, PROPER(TRIM(sales_dataset[[#This Row],[City]]))) -> Delhi | G13: =PROPER(sales_dataset[[#This Row],[Region cleaned]]) -> East | H13: SP4 | I13: =IF(TRIM(sales_dataset[[#This Row],[SalespersonName]])="",I16,PROPER(TRIM(sales_dataset[[#This Row],[SalespersonName]]))) -> Kevin | J13: PROD91 | K13: =PROPER(sales_dataset[[#This Row],[ProductCategory cleaned]]) -> Clothing | L13: =PROPER(sales_dataset[[#This Row],[ProductName]]) -> Watch | M13: =ABS(sales_dataset!W:W) -> 1 | N13: =ABS(sales_dataset[[#This Row],[Column4]]) -> 2000 | O13: =M13*N13 -> 2000
... A511: ORD1450 | B511: 45498 | C511: =IF(TRIM(sales_dataset[[#This Row],[SalesChannel]])="",sales_dataset!C512,PROPER(TRIM(sales_dataset[[#This Row],[SalesChannel]]))) -> Online | D511: CUST192 | E511: =IF(TRIM(sales_dataset[[#This Row],[CustomerName]])="",sales_dataset!F517, PROPER(TRIM(sales_dataset[[#This Row],[CustomerName]]))) -> Sara | F511: =IF(TRIM(sales_dataset[[#This Row],[City]])="", sales_dataset!$H$3, PROPER(TRIM(sales_dataset[[#This Row],[City]]))) -> Chennai | G511: =PROPER(sales_dataset[[#This Row],[Region cleaned]]) -> North | H511: SP9 | I511: =IF(TRIM(sales_dataset[[#This Row],[SalespersonName]])="",I514,PROPER(TRIM(sales_dataset[[#This Row],[SalespersonName]]))) -> Anita | J511: PROD2 | K511: =PROPER(sales_dataset[[#This Row],[ProductCategory cleaned]]) -> Electronics | L511: =PROPER(sales_dataset[[#This Row],[ProductName]]) | M511: =ABS(sales_dataset!W:W) -> 4 | N511: =ABS(sales_dataset[[#This Row],[Column4]]) -> 1500 | O511: =M511*N511 -> 6000

Sheet sales_dataset
A1: Column7 | B1: Column8 | C1: SalesChannel | D1: Column9 | E1: Column10 | F1: CustomerName | G1: Column11 | H1: City | I1: Column12 | J1: Region | K1: Region cleaned | L1: Column2 | M1: Column3 | N1: SalespersonName | O1: Column6 | P1: Column13 | Q1: ProductCategory | R1: ProductCategory cleaned | S1: Column14 | T1: ProductName | U1: Column15 | V1: Quantity | W1: Column1 | X1: Column16 | Y1: UnitPrice | Z1: Column4 | AA1: Column17 | AB1: TotalRevenue | AC1: Column5 | AD1: TotalRevenue2 | AE1: Total Reveneue Corrected
C2: Online | F2: Priya | K2: =IF(TRIM(sales_dataset[[#This Row],[Region]])="", J4, PROPER(TRIM(sales_dataset[[#This Row],[Region]]))) -> NORTH | N2: Kevin | R2: =IF(TRIM(sales_dataset[[#This Row],[ProductCategory]])="", R20, PROPER(TRIM(sales_dataset[[#This Row],[ProductCategory]]))) -> Home | T2: TV | V2: 1 | W2: =IF(TRIM(sales_dataset[[#This Row],[Quantity]])="",V8,PROPER(TRIM(sales_dataset[[#This Row],[Quantity]]))) -> 1 | Y2: 1500 | Z2: =IF(TRIM(sales_dataset[[#This Row],[UnitPrice]])="",Y4,PROPER(TRIM(sales_dataset[[#This Row],[UnitPrice]]))) -> 1500 | AB2: 750 | AC2: =IF(TRIM(sales_dataset[[#This Row],[TotalRevenue]])="",AB4,PROPER(TRIM(sales_dataset[[#This Row],[TotalRevenue]]))) -> 750 | AD2: =ABS(sales_dataset[[#This Row],[Column5]]) -> 750 | AE2: =sales_dataset[[#This Row],[Column17]]*sales_dataset[[#This Row],[Column16]] -> 0
C3: Offline | F3: Sara | H3: Delhi | K3: =IF(TRIM(sales_dataset[[#This Row],[Region]])="", J5, PROPER(TRIM(sales_dataset[[#This Row],[Region]]))) -> North | N3: Raj | Q3: electronics | R3: =IF(TRIM(sales_dataset[[#This Row],[ProductCategory]])="", R21, PROPER(TRIM(sales_dataset[[#This Row],[ProductCategory]]))) -> Electronics | T3: Shirt | V3: 4 | W3: =IF(TRIM(sales_dataset[[#This Row],[Quantity]])="",V9,PROPER(TRIM(sales_dataset[[#This Row],[Quantity]]))) -> 4 | Y3: -100 | Z3: =IF(TRIM(sales_dataset[[#This Row],[UnitPrice]])="",Y5,PROPER(TRIM(sales_dataset[[#This Row],[UnitPrice]]))) -> -100 | AB3: -400 | AC3: =IF(TRIM(sales_dataset[[#This Row],[TotalRevenue]])="",AB5,PROPER(TRIM(sales_dataset[[#This Row],[TotalRevenue]]))) -> -400 | AD3: =ABS(sales_dataset[[#This Row],[Column5]]) -> 400 | AE3: =sales_dataset[[#This Row],[Column17]]*sales_dataset[[#This Row],[Column16]] -> 0
C4: Store | F4: Priya | H4: Delhi | J4: NORTH | K4: =IF(TRIM(sales_dataset[[#This Row],[Region]])="", J6, PROPER(TRIM(sales_dataset[[#This Row],[Region]]))) -> North | N4: Megha | Q4: Home | R4: =IF(TRIM(sales_dataset[[#This Row],[ProductCategory]])="", R22, PROPER(TRIM(sales_dataset[[#This Row],[ProductCategory]]))) -> Home | T4: Shirt | V4: 2 | W4: =IF(TRIM(sales_dataset[[#This Row],[Quantity]])="",V10,PROPER(TRIM(sales_dataset[[#This Row],[Quantity]]))) -> 2 | Z4: =IF(TRIM(sales_dataset[[#This Row],[UnitPrice]])="",Y6,PROPER(TRIM(sales_dataset[[#This Row],[UnitPrice]]))) -> -100 | AC4: =IF(TRIM(sales_dataset[[#This Row],[TotalRevenue]])="",AB6,PROPER(TRIM(sales_dataset[[#This Row],[TotalRevenue]]))) -> -100 | AD4: =ABS(sales_dataset[[#This Row],[Column5]]) -> 100 | AE4: =sales_dataset[[#This Row],[Column17]]*sales_dataset[[#This Row],[Column16]] -> 0
C5: store | F5: Priya | H5: Hyderabad | J5: North | K5: =IF(TRIM(sales_dataset[[#This Row],[Region]])="", J7, PROPER(TRIM(sales_dataset[[#This Row],[Region]]))) -> North | N5: Sam | Q5: electronics | R5: =IF(TRIM(sales_dataset[[#This Row],[ProductCategory]])="", R23, PROPER(TRIM(sales_dataset[[#This Row],[ProductCategory]]))) -> Electronics | T5: TV | V5: 5 | W5: =IF(TRIM(sales_dataset[[#This Row],[Quantity]])="",V11,PROPER(TRIM(sales_dataset[[#This Row],[Quantity]]))) -> 5 | Y5: 1500 | Z5: =IF(TRIM(sales_dataset[[#This Row],[UnitPrice]])="",Y7,PROPER(TRIM(sales_dataset[[#This Row],[UnitPrice]]))) -> 1500 | AB5: 7500 | AC5: =IF(TRIM(sales_dataset[[#This Row],[TotalRevenue]])="",AB7,PROPER(TRIM(sales_dataset[[#This Row],[TotalRevenue]]))) -> 7500 | AD5: =ABS(sales_dataset[[#This Row],[Column5]]) -> 7500 | AE5: =sales_dataset[[#This Row],[Column17]]*sales_dataset[[#This Row],[Column16]] -> 0
C6: ONLINE | F6: priya | H6: Bengaluru | K6: =IF(TRIM(sales_dataset[[#This Row],[Region]])="", J8, PROPER(TRIM(sales_dataset[[#This Row],[Region]]))) -> West | N6: Anita | Q6: Home | R6: =IF(TRIM(sales_dataset[[#This Row],[ProductCategory]])="", R24, PROPER(TRIM(sales_dataset[[#This Row],[ProductCategory]]))) -> Home | T6: TV | V6: 1 | W6: =IF(TRIM(sales_dataset[[#This Row],[Quantity]])="",V12,PROPER(TRIM(sales_dataset[[#This Row],[Quantity]]))) -> 1 | Y6: -100 | Z6: =IF(TRIM(sales_dataset[[#This Row],[UnitPrice]])="",Y8,PROPER(TRIM(sales_dataset[[#This Row],[UnitPrice]]))) -> -100 | AB6: -100 | AC6: =IF(TRIM(sales_dataset[[#This Row],[TotalRevenue]])="",AB8,PROPER(TRIM(sales_dataset[[#This Row],[TotalRevenue]]))) -> -100 | AD6: =ABS(sales_dataset[[#This Row],[Column5]]) -> 100 | AE6: =sales_dataset[[#This Row],[Column17]]*sales_dataset[[#This Row],[Column16]] -> 0
F7: Amit | K7: =IF(TRIM(sales_dataset[[#This Row],[Region]])="", J9, PROPER(TRIM(sales_dataset[[#This Row],[Region]]))) -> NORTH | N7: Sam | Q7: Clothing | R7: =IF(TRIM(sales_dataset[[#This Row],[ProductCategory]])="", R25, PROPER(TRIM(sales_dataset[[#This Row],[ProductCategory]]))) -> Clothing | T7: Shirt | V7: -1 | W7: =IF(TRIM(sales_dataset[[#This Row],[Quantity]])="",V13,PROPER(TRIM(sales_dataset[[#This Row],[Quantity]]))) -> -1 | Y7: 1500 | Z7: =IF(TRIM(sales_dataset[[#This Row],[UnitPrice]])="",Y9,PROPER(TRIM(sales_dataset[[#This Row],[UnitPrice]]))) -> 1500 | AB7: -1500 | AC7: =IF(TRIM(sales_dataset[[#This Row],[TotalRevenue]])="",AB9,PROPER(TRIM(sales_dataset[[#This Row],[TotalRevenue]]))) -> -1500 | AD7: =ABS(sales_dataset[[#This Row],[Column5]]) -> 1500 | AE7: =sales_dataset[[#This Row],[Column17]]*sales_dataset[[#This Row],[Column16]] -> 0
C8: Online | H8: Delhi | J8: West | K8: =IF(TRIM(sales_dataset[[#This Row],[Region]])="", J10, PROPER(TRIM(sales_dataset[[#This Row],[Region]]))) -> West | N8: Megha | Q8: Clothing | R8: =IF(TRIM(sales_dataset[[#This Row],[ProductCategory]])="", R26, PROPER(TRIM(sales_dataset[[#This Row],[ProductCategory]]))) -> Clothing | T8: Laptop | W8: =IF(TRIM(sales_dataset[[#This Row],[Quantity]])="",V14,PROPER(TRIM(sales_dataset[[#This Row],[Quantity]]))) -> -1 | Y8: 500 | Z8: =IF(TRIM(sales_dataset[[#This Row],[UnitPrice]])="",Y10,PROPER(TRIM(sales_dataset[[#This Row],[UnitPrice]]))) -> 500 | AC8: =IF(TRIM(sales_dataset[[#This Row],[TotalRevenue]])="",AB10,PROPER(TRIM(sales_dataset[[#This Row],[TotalRevenue]]))) -> -250 | AD8: =ABS(sales_dataset[[#This Row],[Column5]]) -> 250 | AE8: =sales_dataset[[#This Row],[Column17]]*sales_dataset[[#This Row],[Column16]] -> 0
C9: Offline | F9: John | H9: Mumbai | J9: NORTH | K9: =IF(TRIM(sales_dataset[[#This Row],[Region]])="", J11, PROPER(TRIM(sales_dataset[[#This Row],[Region]]))) -> North | Q9: Home | R9: =IF(TRIM(sales_dataset[[#This Row],[ProductCategory]])="", R27, PROPER(TRIM(sales_dataset[[#This Row],[ProductCategory]]))) -> Home | T9: Sofa | V9: 4 | W9: =IF(TRIM(sales_dataset[[#This Row],[Quantity]])="",V15,PROPER(TRIM(sales_dataset[[#This Row],[Quantity]]))) -> 4 | Y9: 2500 | Z9: =IF(TRIM(sales_dataset[[#This Row],[UnitPrice]])="",Y11,PROPER(TRIM(sales_dataset[[#This Row],[UnitPrice]]))) -> 2500 | AB9: 10000 | AC9: =IF(TRIM(sales_dataset[[#This Row],[TotalRevenue]])="",AB11,PROPER(TRIM(sales_dataset[[#This Row],[TotalRevenue]]))) -> 10000 | AD9: =ABS(sales_dataset[[#This Row],[Column5]]) -> 10000 | AE9: =sales_dataset[[#This Row],[Column17]]*sales_dataset[[#This Row],[Column16]] -> 0
C10: Store | F10: Priya | H10: mumbai | J10: East | K10: =IF(TRIM(sales_dataset[[#This Row],[Region]])="", J12, PROPER(TRIM(sales_dataset[[#This Row],[Region]]))) -> East | N10: Megha | Q10: Electronics | R10: =IF(TRIM(sales_dataset[[#This Row],[ProductCategory]])="", R28, PROPER(TRIM(sales_dataset[[#This Row],[ProductCategory]]))) -> Electronics | T10: Laptop | V10: 5 | W10: =IF(TRIM(sales_dataset[[#This Row],[Quantity]])="",V16,PROPER(TRIM(sales_dataset[[#This Row],[Quantity]]))) -> 5 | Y10: -100 | Z10: =IF(TRIM(sales_dataset[[#This Row],[UnitPrice]])="",Y12,PROPER(TRIM(sales_dataset[[#This Row],[UnitPrice]]))) -> -100 | AB10: -250 | AC10: =IF(TRIM(sales_dataset[[#This Row],[TotalRevenue]])="",AB12,PROPER(TRIM(sales_dataset[[#This Row],[TotalRevenue]]))) -> -250 | AD10: =ABS(sales_dataset[[#This Row],[Column5]]) -> 250 | AE10: =sales_dataset[[#This Row],[Column17]]*sales_dataset[[#This Row],[Column16]] -> 0
C11: store | F11: Sara | J11: North | K11: =IF(TRIM(sales_dataset[[#This Row],[Region]])="", J13, PROPER(TRIM(sales_dataset[[#This Row],[Region]]))) -> North | N11: Raj | Q11: Clothing | R11: =IF(TRIM(sales_dataset[[#This Row],[ProductCategory]])="", R29, PROPER(TRIM(sales_dataset[[#This Row],[ProductCategory]]))) -> Clothing | T11: shirt | V11: 3 | W11: =IF(TRIM(sales_dataset[[#This Row],[Quantity]])="",V17,PROPER(TRIM(sales_dataset[[#This Row],[Quantity]]))) -> 3 | Z11: =IF(TRIM(sales_dataset[[#This Row],[UnitPrice]])="",Y13,PROPER(TRIM(sales_dataset[[#This Row],[UnitPrice]]))) -> 2000 | AC11: =IF(TRIM(sales_dataset[[#This Row],[TotalRevenue]])="",AB13,PROPER(TRIM(sales_dataset[[#This Row],[TotalRevenue]]))) -> 2000 | AD11: =ABS(sales_dataset[[#This Row],[Column5]]) -> 2000 | AE11: =sales_dataset[[#This Row],[Column17]]*sales_dataset[[#This Row],[Column16]] -> 0
C12: ONLINE | F12: priya | H12: Mumbai | J12: East | K12: =IF(TRIM(sales_dataset[[#This Row],[Region]])="", J14, PROPER(TRIM(sales_dataset[[#This Row],[Region]]))) -> East | N12: Raj | R12: =IF(TRIM(sales_dataset[[#This Row],[ProductCategory]])="", R30, PROPER(TRIM(sales_dataset[[#This Row],[ProductCategory]]))) -> Electronics | T12: TV | V12: 4 | W12: =IF(TRIM(sales_dataset[[#This Row],[Quantity]])="",V18,PROPER(TRIM(sales_dataset[[#This Row],[Quantity]]))) -> 4 | Z12: =IF(TRIM(sales_dataset[[#This Row],[UnitPrice]])="",Y14,PROPER(TRIM(sales_dataset[[#This Row],[UnitPrice]]))) -> 0 | AC12: =IF(TRIM(sales_dataset[[#This Row],[TotalRevenue]])="",AB14,PROPER(TRIM(sales_dataset[[#This Row],[TotalRevenue]]))) -> 0 | AD12: =ABS(sales_dataset[[#This Row],[Column5]]) -> 0 | AE12: =sales_dataset[[#This Row],[Column17]]*sales_dataset[[#This Row],[Column16]] -> 0
F13: Sara | H13: Delhi | J13: East | K13: =IF(TRIM(sales_dataset[[#This Row],[Region]])="", J15, PROPER(TRIM(sales_dataset[[#This Row],[Region]]))) -> East | N13: Kevin | R13: =IF(TRIM(sales_dataset[[#This Row],[ProductCategory]])="", R31, PROPER(TRIM(sales_dataset[[#This Row],[ProductCategory]]))) -> Clothing | T13: Watch | V13: 1 | W13: =IF(TRIM(sales_dataset[[#This Row],[Quantity]])="",V19,PROPER(TRIM(sales_dataset[[#This Row],[Quantity]]))) -> 1 | Y13: 2000 | Z13: =IF(TRIM(sales_dataset[[#This Row],[UnitPrice]])="",Y15,PROPER(TRIM(sales_dataset[[#This Row],[UnitPrice]]))) -> 2000 | AB13: 2000 | AC13: =IF(TRIM(sales_dataset[[#This Row],[TotalRevenue]])="",AB15,PROPER(TRIM(sales_dataset[[#This Row],[TotalRevenue]]))) -> 2000 | AD13: =ABS(sales_dataset[[#This Row],[Column5]]) -> 2000 | AE13: =sales_dataset[[#This Row],[Column17]]*sales_dataset[[#This Row],[Column16]] -> 0
C14: Online | F14: Priya | H14: Mumbai | J14: South | K14: =IF(TRIM(sales_dataset[[#This Row],[Region]])="", J16, PROPER(TRIM(sales_dataset[[#This Row],[Region]]))) -> South | N14: Anita | R14: =IF(TRIM(sales_dataset[[#This Row],[ProductCategory]])="", R32, PROPER(TRIM(sales_dataset[[#This Row],[ProductCategory]]))) -> Electronics | T14: TV | V14: -1 | W14: =IF(TRIM(sales_dataset[[#This Row],[Quantity]])="",V20,PROPER(TRIM(sales_dataset[[#This Row],[Quantity]]))) -> -1 | Z14: =IF(TRIM(sales_dataset[[#This Row],[UnitPrice]])="",Y16,PROPER(TRIM(sales_dataset[[#This Row],[UnitPrice]]))) -> 2500 | AC14: =IF(TRIM(sales_dataset[[#This Row],[TotalRevenue]])="",AB16,PROPER(TRIM(sales_dataset[[#This Row],[TotalRevenue]]))) -> 5000 | AD14: =ABS(sales_dataset[[#This Row],[Column5]]) -> 5000 | AE14: =sales_dataset[[#This Row],[Column17]]*sales_dataset[[#This Row],[Column16]] -> 0
C15: Offline | F15: priya | H15: Bengaluru | J15: South | K15: =IF(TRIM(sales_dataset[[#This Row],[Region]])="", J17, PROPER(TRIM(sales_dataset[[#This Row],[Region]]))) -> South | R15: =IF(TRIM(sales_dataset[[#This Row],[ProductCategory]])="", R33, PROPER(TRIM(sales_dataset[[#This Row],[ProductCategory]]))) -> Electronics | T15: Shirt | V15: -1 | W15: =IF(TRIM(sales_dataset[[#This Row],[Quantity]])="",V21,PROPER(TRIM(sales_dataset[[#This Row],[Quantity]]))) -> -1 | Y15: 2500 | Z15: =IF(TRIM(sales_dataset[[#This Row],[UnitPrice]])="",Y17,PROPER(TRIM(sales_dataset[[#This Row],[UnitPrice]]))) -> 2500 | AB15: -2500 | AC15: =IF(TRIM(sales_dataset[[#This Row],[TotalRevenue]])="",AB17,PROPER(TRIM(sales_dataset[[#This Row],[TotalRevenue]]))) -> -2500 | AD15: =ABS(sales_dataset[[#This Row],[Column5]]) -> 2500 | AE15: =sales_dataset[[#This Row],[Column17]]*sales_dataset[[#This Row],[Column16]] -> 0
C16: Store | F16: Sara | J16: East | K16: =IF(TRIM(sales_dataset[[#This Row],[Region]])="", J18, PROPER(TRIM(sales_dataset[[#This Row],[Region]]))) -> East | Q16: Home | R16: =IF(TRIM(sales_dataset[[#This Row],[ProductCategory]])="", R34, PROPER(TRIM(sales_dataset[[#This Row],[ProductCategory]]))) -> Home | T16: Watch | V16: 2 | W16: =IF(TRIM(sales_dataset[[#This Row],[Quantity]])="",V22,PROPER(TRIM(sales_dataset[[#This Row],[Quantity]]))) -> 2 | Y16: 2500 | Z16: =IF(TRIM(sales_dataset[[#This Row],[UnitPrice]])="",Y18,PROPER(TRIM(sales_dataset[[#This Row],[UnitPrice]]))) -> 2500 | AB16: 5000 | AC16: =IF(TRIM(sales_dataset[[#This Row],[TotalRevenue]])="",AB18,PROPER(TRIM(sales_dataset[[#This Row],[TotalRevenue]]))) -> 5000 | AD16: =ABS(sales_dataset[[#This Row],[Column5]]) -> 5000 | AE16: =sales_dataset[[#This Row],[Column17]]*sales_dataset[[#This Row],[Column16]] -> 0
C17: store | J17: West | K17: =IF(TRIM(sales_dataset[[#This Row],[Region]])="", J19, PROPER(TRIM(sales_dataset[[#This Row],[Region]]))) -> West | N17: Sam | Q17: Electronics | R17: =IF(TRIM(sales_dataset[[#This Row],[ProductCategory]])="", R35, PROPER(TRIM(sales_dataset[[#This Row],[ProductCategory]]))) -> Electronics | T17: Watch | V17: 2 | W17: =IF(TRIM(sales_dataset[[#This Row],[Quantity]])="",V23,PROPER(TRIM(sales_dataset[[#This Row],[Quantity]]))) -> 2 | Z17: =IF(TRIM(sales_dataset[[#This Row],[UnitPrice]])="",Y19,PROPER(TRIM(sales_dataset[[#This Row],[UnitPrice]]))) -> 1500 | AC17: =IF(TRIM(sales_dataset[[#This Row],[TotalRevenue]])="",AB19,PROPER(TRIM(sales_dataset[[#This Row],[TotalRevenue]]))) -> 4500 | AD17: =ABS(sales_dataset[[#This Row],[Column5]]) -> 4500 | AE17: =sales_dataset[[#This Row],[Column17]]*sales_dataset[[#This Row],[Column16]] -> 0
C18: ONLINE | H18: Delhi | J18: South | K18: =IF(TRIM(sales_dataset[[#This Row],[Region]])="", J20, PROPER(TRIM(sales_dataset[[#This Row],[Region]]))) -> South | N18: Anita | Q18: Home | R18: =IF(TRIM(sales_dataset[[#This Row],[ProductCategory]])="", R36, PROPER(TRIM(sales_dataset[[#This Row],[ProductCategory]]))) -> Home | T18: Sofa | V18: 2 | W18: =IF(TRIM(sales_dataset[[#This Row],[Quantity]])="",V24,PROPER(TRIM(sales_dataset[[#This Row],[Quantity]]))) -> 2 | Y18: -100 | Z18: =IF(TRIM(sales_dataset[[#This Row],[UnitPrice]])="",Y20,PROPER(TRIM(sales_dataset[[#This Row],[UnitPrice]]))) -> -100 | AB18: -200 | AC18: =IF(TRIM(sales_dataset[[#This Row],[TotalRevenue]])="",AB20,PROPER(TRIM(sales_dataset[[#This Row],[TotalRevenue]]))) -> -200 | AD18: =ABS(sales_dataset[[#This Row],[Column5]]) -> 200 | AE18: =sales_dataset[[#This Row],[Column17]]*sales_dataset[[#This Row],[Column16]] -> 0
F19: David | H19: Hyderabad | J19: South | K19: =IF(TRIM(sales_dataset[[#This Row],[Region]])="", J21, PROPER(TRIM(sales_dataset[[#This Row],[Region]]))) -> South | N19: Sam | Q19: Clothing | R19: =IF(TRIM(sales_dataset[[#This Row],[ProductCategory]])="", R37, PROPER(TRIM(sales_dataset[[#This Row],[ProductCategory]]))) -> Clothing | T19: shirt | V19: 3 | W19: =IF(TRIM(sales_dataset[[#This Row],[Quantity]])="",V25,PROPER(TRIM(sales_dataset[[#This Row],[Quantity]]))) -> 3 | Y19: 1500 | Z19: =IF(TRIM(sales_dataset[[#This Row],[UnitPrice]])="",Y21,PROPER(TRIM(sales_dataset[[#This Row],[UnitPrice]]))) -> 1500 | AB19: 4500 | AC19: =IF(TRIM(sales_dataset[[#This Row],[TotalRevenue]])="",AB21,PROPER(TRIM(sales_dataset[[#This Row],[TotalRevenue]]))) -> 4500 | AD19: =ABS(sales_dataset[[#This Row],[Column5]]) -> 4500 | AE19: =sales_dataset[[#This Row],[Column17]]*sales_dataset[[#This Row],[Column16]] -> 0
C20: Online | F20: Amit | H20: Bengaluru | J20: South | K20: =IF(TRIM(sales_dataset[[#This Row],[Region]])="", J22, PROPER(TRIM(sales_dataset[[#This Row],[Region]]))) -> South | N20: Anita | R20: =IF(TRIM(sales_dataset[[#This Row],[ProductCategory]])="", R38, PROPER(TRIM(sales_dataset[[#This Row],[ProductCategory]]))) -> Home | T20: TV | V20: 4 | W20: =IF(TRIM(sales_dataset[[#This Row],[Quantity]])="",V26,PROPER(TRIM(sales_dataset[[#This Row],[Quantity]]))) -> 4 | Y20: 2000 | Z20: =IF(TRIM(sales_dataset[[#This Row],[UnitPrice]])="",Y22,PROPER(TRIM(sales_dataset[[#This Row],[UnitPrice]]))) -> 2000 | AB20: 8000 | AC20: =IF(TRIM(sales_dataset[[#This Row],[TotalRevenue]])="",AB22,PROPER(TRIM(sales_dataset[[#This Row],[TotalRevenue]]))) -> 8000 | AD20: =ABS(sales_dataset[[#This Row],[Column5]]) -> 8000 | AE20: =sales_dataset[[#This Row],[Column17]]*sales_dataset[[#This Row],[Column16]] -> 0
C21: Offline | F21: Sara | H21: Mumbai | J21: South | K21: =IF(TRIM(sales_dataset[[#This Row],[Region]])="", J23, PROPER(TRIM(sales_dataset[[#This Row],[Region]]))) -> South | N21: Megha | R21: =IF(TRIM(sales_dataset[[#This Row],[ProductCategory]])="", R39, PROPER(TRIM(sales_dataset[[#This Row],[ProductCategory]]))) -> Clothing | T21: Sofa | V21: 5 | W21: =IF(TRIM(sales_dataset[[#This Row],[Quantity]])="",V27,PROPER(TRIM(sales_dataset[[#This Row],[Quantity]]))) -> 5 | Y21: 2500 | Z21: =IF(TRIM(sales_dataset[[#This Row],[UnitPrice]])="",Y23,PROPER(TRIM(sales_dataset[[#This Row],[UnitPrice]]))) -> 2500 | AB21: 12500 | AC21: =IF(TRIM(sales_dataset[[#This Row],[TotalRevenue]])="",AB23,PROPER(TRIM(sales_dataset[[#This Row],[TotalRevenue]]))) -> 12500 | AD21: =ABS(sales_dataset[[#This Row],[Column5]]) -> 12500 | AE21: =sales_dataset[[#This Row],[Column17]]*sales_dataset[[#This Row],[Column16]] -> 0
C22: Store | F22: Amit | H22: Delhi | J22: North | K22: =IF(TRIM(sales_dataset[[#This Row],[Region]])="", J24, PROPER(TRIM(sales_dataset[[#This Row],[Region]]))) -> North | N22: Megha | R22: =IF(TRIM(sales_dataset[[#This Row],[ProductCategory]])="", R40, PROPER(TRIM(sales_dataset[[#This Row],[ProductCategory]]))) -> Electronics | T22: shirt | V22: 4 | W22: =IF(TRIM(sales_dataset[[#This Row],[Quantity]])="",V28,PROPER(TRIM(sales_dataset[[#This Row],[Quantity]]))) -> 4 | Y22: 2000 | Z22: =IF(TRIM(sales_dataset[[#This Row],[UnitPrice]])="",Y24,PROPER(TRIM(sales_dataset[[#This Row],[UnitPrice]]))) -> 2000 | AB22: 8000 | AC22: =IF(TRIM(sales_dataset[[#This Row],[TotalRevenue]])="",AB24,PROPER(TRIM(sales_dataset[[#This Row],[TotalRevenue]]))) -> 8000 | AD22: =ABS(sales_dataset[[#This Row],[Column5]]) -> 8000 | AE22: =sales_dataset[[#This Row],[Column17]]*sales_dataset[[#This Row],[Column16]] -> 0
C23: store | F23: Priya | H23: Bengaluru | J23: East | K23: =IF(TRIM(sales_dataset[[#This Row],[Region]])="", J25, PROPER(TRIM(sales_dataset[[#This Row],[Region]]))) -> East | N23: Anita | Q23: Clothing | R23: =IF(TRIM(sales_dataset[[#This Row],[ProductCategory]])="", R41, PROPER(TRIM(sales_dataset[[#This Row],[ProductCategory]]))) -> Clothing | T23: Laptop | V23: 2 | W23: =IF(TRIM(sales_dataset[[#This Row],[Quantity]])="",V29,PROPER(TRIM(sales_dataset[[#This Row],[Quantity]]))) -> 2 | Y23: 2000 | Z23: =IF(TRIM(sales_dataset[[#This Row],[UnitPrice]])="",Y25,PROPER(TRIM(sales_dataset[[#This Row],[UnitPrice]]))) -> 2000 | AB23: 4000 | AC23: =IF(TRIM(sales_dataset[[#This Row],[TotalRevenue]])="",AB25,PROPER(TRIM(sales_dataset[[#This Row],[TotalRevenue]]))) -> 4000 | AD23: =ABS(sales_dataset[[#This Row],[Column5]]) -> 4000 | AE23: =sales_dataset[[#This Row],[Column17]]*sales_dataset[[#This Row],[Column16]] -> 0
C24: ONLINE | F24: Priya | H24: Mumbai | J24: North | K24: =IF(TRIM(sales_dataset[[#This Row],[Region]])="", J26, PROPER(TRIM(sales_dataset[[#This Row],[Region]]))) -> North | N24: Kevin | Q24: electronics | R24: =IF(TRIM(sales_dataset[[#This Row],[ProductCategory]])="", R42, PROPER(TRIM(sales_dataset[[#This Row],[ProductCategory]]))) -> Electronics | T24: Watch | V24: 3 | W24: =IF(TRIM(sales_dataset[[#This Row],[Quantity]])="",V30,PROPER(TRIM(sales_dataset[[#This Row],[Quantity]]))) -> 3 | Y24: 2500 | Z24: =IF(TRIM(sales_dataset[[#This Row],[UnitPrice]])="",Y26,PROPER(TRIM(sales_dataset[[#This Row],[UnitPrice]]))) -> 2500 | AB24: 7500 | AC24: =IF(TRIM(sales_dataset[[#This Row],[TotalRevenue]])="",AB26,PROPER(TRIM(sales_dataset[[#This Row],[TotalRevenue]]))) -> 7500 | AD24: =ABS(sales_dataset[[#This Row],[Column5]]) -> 7500 | AE24: =sales_dataset[[#This Row],[Column17]]*sales_dataset[[#This Row],[Column16]] -> 0
F25: Priya | H25: Delhi | J25: NORTH | K25: =IF(TRIM(sales_dataset[[#This Row],[Region]])="", J27, PROPER(TRIM(sales_dataset[[#This Row],[Region]]))) -> North | N25: Megha | Q25: Home | R25: =IF(TRIM(sales_dataset[[#This Row],[ProductCategory]])="", R43, PROPER(TRIM(sales_dataset[[#This Row],[ProductCategory]]))) -> Home | T25: Sofa | V25: -1 | W25: =IF(TRIM(sales_dataset[[#This Row],[Quantity]])="",V31,PROPER(TRIM(sales_dataset[[#This Row],[Quantity]]))) -> -1 | Y25: 1500 | Z25: =IF(TRIM(sales_dataset[[#This Row],[UnitPrice]])="",Y27,PROPER(TRIM(sales_dataset[[#This Row],[UnitPrice]]))) -> 1500 | AB25: -1500 | AC25: =IF(TRIM(sales_dataset[[#This Row],[TotalRevenue]])="",AB27,PROPER(TRIM(sales_dataset[[#This Row],[TotalRevenue]]))) -> -1500 | AD25: =ABS(sales_dataset[[#This Row],[Column5]]) -> 1500 | AE25: =sales_dataset[[#This Row],[Column17]]*sales_dataset[[#This Row],[Column16]] -> 0
C26: Online | F26: Amit | H26: mumbai | J26: NORTH | K26: =IF(TRIM(sales_dataset[[#This Row],[Region]])="", J28, PROPER(TRIM(sales_dataset[[#This Row],[Region]]))) -> North | N26: Kevin | Q26: Electronics | R26: =IF(TRIM(sales_dataset[[#This Row],[ProductCategory]])="", R44, PROPER(TRIM(sales_dataset[[#This Row],[ProductCategory]]))) -> Electronics | T26: Laptop | W26: =IF(TRIM(sales_dataset[[#This Row],[Quantity]])="",V32,PROPER(TRIM(sales_dataset[[#This Row],[Quantity]]))) -> 0 | Y26: 1500 | Z26: =IF(TRIM(sales_dataset[[#This Row],[UnitPrice]])="",Y28,PROPER(TRIM(sales_dataset[[#This Row],[UnitPrice]]))) -> 1500 | AC26: =IF(TRIM(sales_dataset[[#This Row],[TotalRevenue]])="",AB28,PROPER(TRIM(sales_dataset[[#This Row],[TotalRevenue]]))) -> 0 | AD26: =ABS(sales_dataset[[#This Row],[Column5]]) -> 0 | AE26: =sales_dataset[[#This Row],[Column17]]*sales_dataset[[#This Row],[Column16]] -> 0
C27: Offline | H27: Chennai | K27: =IF(TRIM(sales_dataset[[#This Row],[Region]])="", J29, PROPER(TRIM(sales_dataset[[#This Row],[Region]]))) -> North | N27: Megha | Q27: Clothing | R27: =IF(TRIM(sales_dataset[[#This Row],[ProductCategory]])="", R45, PROPER(TRIM(sales_dataset[[#This Row],[ProductCategory]]))) -> Clothing | T27: TV | V27: 2 | W27: =IF(TRIM(sales_dataset[[#This Row],[Quantity]])="",V33,PROPER(TRIM(sales_dataset[[#This Row],[Quantity]]))) -> 2 | Y27: 2500 | Z27: =IF(TRIM(sales_dataset[[#This Row],[UnitPrice]])="",Y29,PROPER(TRIM(sales_dataset[[#This Row],[UnitPrice]]))) -> 2500 | AB27: 5000 | AC27: =IF(TRIM(sales_dataset[[#This Row],[TotalRevenue]])="",AB29,PROPER(TRIM(sales_dataset[[#This Row],[TotalRevenue]]))) -> 5000 | AD27: =ABS(sales_dataset[[#This Row],[Column5]]) -> 5000 | AE27: =sales_dataset[[#This Row],[Column17]]*sales_dataset[[#This Row],[Column16]] -> 0
C28: Store | F28: Sara | H28: Hyderabad | J28: NORTH | K28: =IF(TRIM(sales_dataset[[#This Row],[Region]])="", J30, PROPER(TRIM(sales_dataset[[#This Row],[Region]]))) -> North | Q28: electronics | R28: =IF(TRIM(sales_dataset[[#This Row],[ProductCategory]])="", R46, PROPER(TRIM(sales_dataset[[#This Row],[ProductCategory]]))) -> Electronics | T28: TV | V28: -1 | W28: =IF(TRIM(sales_dataset[[#This Row],[Quantity]])="",V34,PROPER(TRIM(sales_dataset[[#This Row],[Quantity]]))) -> -1 | Z28: =IF(TRIM(sales_dataset[[#This Row],[UnitPrice]])="",Y30,PROPER(TRIM(sales_dataset[[#This Row],[UnitPrice]]))) -> -100 | AC28: =IF(TRIM(sales_dataset[[#This Row],[TotalRevenue]])="",AB30,PROPER(TRIM(sales_dataset[[#This Row],[TotalRevenue]]))) -> -400 | AD28: =ABS(sales_dataset[[#This Row],[Column5]]) -> 400 | AE28: =sales_dataset[[#This Row],[Column17]]*sales_dataset[[#This Row],[Column16]] -> 0
C29: store | H29: Mumbai | J29: North | K29: =IF(TRIM(sales_dataset[[#This Row],[Region]])="", J31, PROPER(TRIM(sales_dataset[[#This Row],[Region]]))) -> North | N29: Raj | Q29: electronics | R29: =IF(TRIM(sales_dataset[[#This Row],[ProductCategory]])="", R47, PROPER(TRIM(sales_dataset[[#This Row],[ProductCategory]]))) -> Electronics | T29: Shirt | V29: 1 | W29: =IF(TRIM(sales_dataset[[#This Row],[Quantity]])="",V35,PROPER(TRIM(sales_dataset[[#This Row],[Quantity]]))) -> 1 | Y29: -100 | Z29: =IF(TRIM(sales_dataset[[#This Row],[UnitPrice]])="",Y31,PROPER(TRIM(sales_dataset[[#This Row],[UnitPrice]]))) -> -100 | AB29: -100 | AC29: =IF(TRIM(sales_dataset[[#This Row],[TotalRevenue]])="",AB31,PROPER(TRIM(sales_dataset[[#This Row],[TotalRevenue]]))) -> -100 | AD29: =ABS(sales_dataset[[#This Row],[Column5]]) -> 100 | AE29: =sales_dataset[[#This Row],[Column17]]*sales_dataset[[#This Row],[Column16]] -> 0
C30: ONLINE | F30: David | H30: mumbai | K30: =IF(TRIM(sales_dataset[[#This Row],[Region]])="", J32, PROPER(TRIM(sales_dataset[[#This Row],[Region]]))) -> NORTH | N30: Raj | Q30: Electronics | R30: =IF(TRIM(sales_dataset[[#This Row],[ProductCategory]])="", R48, PROPER(TRIM(sales_dataset[[#This Row],[ProductCategory]]))) -> Electronics | T30: Laptop | V30: 4 | W30: =IF(TRIM(sales_dataset[[#This Row],[Quantity]])="",V36,PROPER(TRIM(sales_dataset[[#This Row],[Quantity]]))) -> 4 | Y30: -100 | Z30: =IF(TRIM(sales_dataset[[#This Row],[UnitPrice]])="",Y32,PROPER(TRIM(sales_dataset[[#This Row],[UnitPrice]]))) -> -100 | AB30: -400 | AC30: =IF(TRIM(sales_dataset[[#This Row],[TotalRevenue]])="",AB32,PROPER(TRIM(sales_dataset[[#This Row],[TotalRevenue]]))) -> -400 | AD30: =ABS(sales_dataset[[#This Row],[Column5]]) -> 400 | AE30: =sales_dataset[[#This Row],[Column17]]*sales_dataset[[#This Row],[Column16]] -> 0
H31: Mumbai | J31: East | K31: =IF(TRIM(sales_dataset[[#This Row],[Region]])="", J33, PROPER(TRIM(sales_dataset[[#This Row],[Region]]))) -> East | Q31: Clothing | R31: =IF(TRIM(sales_dataset[[#This Row],[ProductCategory]])="", R49, PROPER(TRIM(sales_dataset[[#This Row],[ProductCategory]]))) -> Clothing | T31: Laptop | V31: 3 | W31: =IF(TRIM(sales_dataset[[#This Row],[Quantity]])="",V37,PROPER(TRIM(sales_dataset[[#This Row],[Quantity]]))) -> 3 | Z31: =IF(TRIM(sales_dataset[[#This Row],[UnitPrice]])="",Y33,PROPER(TRIM(sales_dataset[[#This Row],[UnitPrice]]))) -> -100 | AC31: =IF(TRIM(sales_dataset[[#This Row],[TotalRevenue]])="",AB33,PROPER(TRIM(sales_dataset[[#This Row],[TotalRevenue]]))) -> -200 | AD31: =ABS(sales_dataset[[#This Row],[Column5]]) -> 200 | AE31: =sales_dataset[[#This Row],[Column17]]*sales_dataset[[#This Row],[Column16]] -> 0
C32: Online | F32: Amit | H32: Chennai | J32: NORTH | K32: =IF(TRIM(sales_dataset[[#This Row],[Region]])="", J34, PROPER(TRIM(sales_dataset[[#This Row],[Region]]))) -> North | N32: Anita | Q32: electronics | R32: =IF(TRIM(sales_dataset[[#This Row],[ProductCategory]])="", R50, PROPER(TRIM(sales_dataset[[#This Row],[ProductCategory]]))) -> Electronics | T32: Sofa | W32: =IF(TRIM(sales_dataset[[#This Row],[Quantity]])="",V38,PROPER(TRIM(sales_dataset[[#This Row],[Quantity]]))) -> 4 | Y32: 2000 | Z32: =IF(TRIM(sales_dataset[[#This Row],[UnitPrice]])="",Y34,PROPER(TRIM(sales_dataset[[#This Row],[UnitPrice]]))) -> 2000 | AC32: =IF(TRIM(sales_dataset[[#This Row],[TotalRevenue]])="",AB34,PROPER(TRIM(sales_dataset[[#This Row],[TotalRevenue]]))) -> 0 | AD32: =ABS(sales_dataset[[#This Row],[Column5]]) -> 0 | AE32: =sales_dataset[[#This Row],[Column17]]*sales_dataset[[#This Row],[Column16]] -> 0
C33: Offline | F33: priya | H33: Chennai | J33: South | K33: =IF(TRIM(sales_dataset[[#This Row],[Region]])="", J35, PROPER(TRIM(sales_dataset[[#This Row],[Region]]))) -> South | N33: Sam | R33: =IF(TRIM(sales_dataset[[#This Row],[ProductCategory]])="", R51, PROPER(TRIM(sales_dataset[[#This Row],[ProductCategory]]))) -> Electronics | T33: shirt | V33: 2 | W33: =IF(TRIM(sales_dataset[[#This Row],[Quantity]])="",V39,PROPER(TRIM(sales_dataset[[#This Row],[Quantity]]))) -> 2 | Y33: -100 | Z33: =IF(TRIM(sales_dataset[[#This Row],[UnitPrice]])="",Y35,PROPER(TRIM(sales_dataset[[#This Row],[UnitPrice]]))) -> -100 | AB33: -200 | AC33: =IF(TRIM(sales_dataset[[#This Row],[TotalRevenue]])="",AB35,PROPER(TRIM(sales_dataset[[#This Row],[TotalRevenue]]))) -> -200 | AD33: =ABS(sales_dataset[[#This Row],[Column5]]) -> 200 | AE33: =sales_dataset[[#This Row],[Column17]]*sales_dataset[[#This Row],[Column16]] -> 0
C34: Store | J34: NORTH | K34: =IF(TRIM(sales_dataset[[#This Row],[Region]])="", J36, PROPER(TRIM(sales_dataset[[#This Row],[Region]]))) -> North | N34: Raj | Q34: Electronics | R34: =IF(TRIM(sales_dataset[[#This Row],[ProductCategory]])="", R52, PROPER(TRIM(sales_dataset[[#This Row],[ProductCategory]]))) -> Electronics | T34: Watch | V34: 3 | W34: =IF(TRIM(sales_dataset[[#This Row],[Quantity]])="",V40,PROPER(TRIM(sales_dataset[[#This Row],[Quantity]]))) -> 3 | Z34: =IF(TRIM(sales_dataset[[#This Row],[UnitPrice]])="",Y36,PROPER(TRIM(sales_dataset[[#This Row],[UnitPrice]]))) -> -100 | AC34: =IF(TRIM(sales_dataset[[#This Row],[TotalRevenue]])="",AB36,PROPER(TRIM(sales_dataset[[#This Row],[TotalRevenue]]))) -> -100 | AD34: =ABS(sales_dataset[[#This Row],[Column5]]) -> 100 | AE34: =sales_dataset[[#This Row],[Column17]]*sales_dataset[[#This Row],[Column16]] -> 0
C35: store | F35: David | H35: Bengaluru | J35: West | K35: =IF(TRIM(sales_dataset[[#This Row],[Region]])="", J37, PROPER(TRIM(sales_dataset[[#This Row],[Region]]))) -> West | N35: Megha | R35: =IF(TRIM(sales_dataset[[#This Row],[ProductCategory]])="", R53, PROPER(TRIM(sales_dataset[[#This Row],[ProductCategory]]))) -> Clothing | T35: shirt | W35: =IF(TRIM(sales_dataset[[#This Row],[Quantity]])="",V41,PROPER(TRIM(sales_dataset[[#This Row],[Quantity]]))) -> -1 | Y35: 2000 | Z35: =IF(TRIM(sales_dataset[[#This Row],[UnitPrice]])="",Y37,PROPER(TRIM(sales_dataset[[#This Row],[UnitPrice]]))) -> 2000 | AC35: =IF(TRIM(sales_dataset[[#This Row],[TotalRevenue]])="",AB37,PROPER(TRIM(sales_dataset[[#This Row],[TotalRevenue]]))) -> -100 | AD35: =ABS(sales_dataset[[#This Row],[Column5]]) -> 100 | AE35: =sales_dataset[[#This Row],[Column17]]*sales_dataset[[#This Row],[Column16]] -> 0
C36: ONLINE | F36: Sara | H36: Hyderabad | J36: South | K36: =IF(TRIM(sales_dataset[[#This Row],[Region]])="", J38, PROPER(TRIM(sales_dataset[[#This Row],[Region]]))) -> South | N36: Megha | Q36: Electronics | R36: =IF(TRIM(sales_dataset[[#This Row],[ProductCategory]])="", R54, PROPER(TRIM(sales_dataset[[#This Row],[ProductCategory]]))) -> Electronics | T36: shirt | V36: 1 | W36: =IF(TRIM(sales_dataset[[#This Row],[Quantity]])="",V42,PROPER(TRIM(sales_dataset[[#This Row],[Quantity]]))) -> 1 | Y36: -100 | Z36: =IF(TRIM(sales_dataset[[#This Row],[UnitPrice]])="",Y38,PROPER(TRIM(sales_dataset[[#This Row],[UnitPrice]]))) -> -100 | AB36: -100 | AC36: =IF(TRIM(sales_dataset[[#This Row],[TotalRevenue]])="",AB38,PROPER(TRIM(sales_dataset[[#This Row],[TotalRevenue]]))) -> -100 | AD36: =ABS(sales_dataset[[#This Row],[Column5]]) -> 100 | AE36: =sales_dataset[[#This Row],[Column17]]*sales_dataset[[#This Row],[Column16]] -> 0
F37: Sara | H37: Hyderabad | J37: South | K37: =IF(TRIM(sales_dataset[[#This Row],[Region]])="", J39, PROPER(TRIM(sales_dataset[[#This Row],[Region]]))) -> South | N37: Raj | Q37: Home | R37: =IF(TRIM(sales_dataset[[#This Row],[ProductCategory]])="", R55, PROPER(TRIM(sales_dataset[[#This Row],[ProductCategory]]))) -> Home | T37: Watch | V37: 1 | W37: =IF(TRIM(sales_dataset[[#This Row],[Quantity]])="",V43,PROPER(TRIM(sales_dataset[[#This Row],[Quantity]]))) -> 1 | Y37: -100 | Z37: =IF(TRIM(sales_dataset[[#This Row],[UnitPrice]])="",Y39,PROPER(TRIM(sales_dataset[[#This Row],[UnitPrice]]))) -> -100 | AB37: -100 | AC37: =IF(TRIM(sales_dataset[[#This Row],[TotalRevenue]])="",AB39,PROPER(TRIM(sales_dataset[[#This Row],[TotalRevenue]]))) -> -100 | AD37: =ABS(sales_dataset[[#This Row],[Column5]]) -> 100 | AE37: =sales_dataset[[#This Row],[Column17]]*sales_dataset[[#This Row],[Column16]] -> 0
C38: Online | F38: Amit | H38: Mumbai | J38: South | K38: =IF(TRIM(sales_dataset[[#This Row],[Region]])="", J40, PROPER(TRIM(sales_dataset[[#This Row],[Region]]))) -> South | N38: Raj | Q38: Home | R38: =IF(TRIM(sales_dataset[[#This Row],[ProductCategory]])="", R56, PROPER(TRIM(sales_dataset[[#This Row],[ProductCategory]]))) -> Home | T38: Shirt | V38: 4 | W38: =IF(TRIM(sales_dataset[[#This Row],[Quantity]])="",V44,PROPER(TRIM(sales_dataset[[#This Row],[Quantity]]))) -> 4 | Z38: =IF(TRIM(sales_dataset[[#This Row],[UnitPrice]])="",Y40,PROPER(TRIM(sales_dataset[[#This Row],[UnitPrice]]))) -> 1500 | AC38: =IF(TRIM(sales_dataset[[#This Row],[TotalRevenue]])="",AB40,PROPER(TRIM(sales_dataset[[#This Row],[TotalRevenue]]))) -> 3000 | AD38: =ABS(sales_dataset[[#This Row],[Column5]]) -> 3000 | AE38: =sales_dataset[[#This Row],[Column17]]*sales_dataset[[#This Row],[Column16]] -> 0
C39: Offline | F39: John | H39: Chennai | K39: =IF(TRIM(sales_dataset[[#This Row],[Region]])="", J41, PROPER(TRIM(sales_dataset[[#This Row],[Region]]))) -> South | N39: Sam | Q39: Clothing | R39: =IF(TRIM(sales_dataset[[#This Row],[ProductCategory]])="", R57, PROPER(TRIM(sales_dataset[[#This Row],[ProductCategory]]))) -> Clothing | T39: shirt | V39: 3 | W39: =IF(TRIM(sales_dataset[[#This Row],[Quantity]])="",V45,PROPER(TRIM(sales_dataset[[#This Row],[Quantity]]))) -> 3 | Y39: -100 | Z39: =IF(TRIM(sales_dataset[[#This Row],[UnitPrice]])="",Y41,PROPER(TRIM(sales_dataset[[#This Row],[UnitPrice]]))) -> -100 | AB39: -300 | AC39: =IF(TRIM(sales_dataset[[#This Row],[TotalRevenue]])="",AB41,PROPER(TRIM(sales_dataset[[#This Row],[TotalRevenue]]))) -> -300 | AD39: =ABS(sales_dataset[[#This Row],[Column5]]) -> 300 | AE39: =sales_dataset[[#This Row],[Column17]]*sales_dataset[[#This Row],[Column16]] -> 0
C40: Store | F40: David | H40: Hyderabad | J40: NORTH | K40: =IF(TRIM(sales_dataset[[#This Row],[Region]])="", J42, PROPER(TRIM(sales_dataset[[#This Row],[Region]]))) -> North | N40: Raj | Q40: electronics | R40: =IF(TRIM(sales_dataset[[#This Row],[ProductCategory]])="", R58, PROPER(TRIM(sales_dataset[[#This Row],[ProductCategory]]))) -> Electronics | T40: Shirt | V40: 2 | W40: =IF(TRIM(sales_dataset[[#This Row],[Quantity]])="",V46,PROPER(TRIM(sales_dataset[[#This Row],[Quantity]]))) -> 2 | Y40: 1500 | Z40: =IF(TRIM(sales_dataset[[#This Row],[UnitPrice]])="",Y42,PROPER(TRIM(sales_dataset[[#This Row],[UnitPrice]]))) -> 1500 | AB40: 3000 | AC40: =IF(TRIM(sales_dataset[[#This Row],[TotalRevenue]])="",AB42,PROPER(TRIM(sales_dataset[[#This Row],[TotalRevenue]]))) -> 3000 | AD40: =ABS(sales_dataset[[#This Row],[Column5]]) -> 3000 | AE40: =sales_dataset[[#This Row],[Column17]]*sales_dataset[[#This Row],[Column16]] -> 0
...
